<sdf version="1.6">
    <model name="X1" canonical_link="X1_1_base_link">
        <enable_wind>1</enable_wind>
        <static>0</static>
        <link name="X1_1_base_link">
            <inertial>
                <pose frame="">0.0 0.0 0.062 0 0 0</pose>
                <mass>46.034</mass>
                <inertia>
                    <ixx>0.613201</ixx>
                    <ixy>-0.0236401</ixy>
                    <ixz>-0.1197</ixz>
                    <iyy>1.7496</iyy>
                    <iyz>-0.00154411</iyz>
                    <izz>2.0406</izz>
                </inertia>
            </inertial>
            <collision name="X1_1_base_link_collision">
                <pose frame="">0.0 0.0 0.048 0 0 0</pose>
                <geometry>
                    <box>
                        <size>0.39496000000000003 0.22836 0.020000000000000004</size>
                    </box>
                </geometry>
            </collision>
            <collision name="X1_1_base_link_collision_bottom">
                <pose frame="">0.0 0.0 0.0184 0 0 0</pose>
                <geometry>
                    <box>
                        <size>0.32000000000000006 0.22836 0.038000000000000006</size>
                    </box>
                </geometry>
            </collision>
            <collision name="X1_1_base_link_collision_1">
                <pose frame="">0.0 0.0 0.07425000000000001 0 0 0</pose>
                <geometry>
                    <box>
                        <size>0.315968 0.22836 0.0495</size>
                    </box>
                </geometry>
            </collision>
            <collision name="top_plate_collision">
                <pose frame="">0.03248 0.0 0.098 0 0 0</pose>
                <geometry>
                    <mesh>
                        <uri>model://X1/meshes/top_plate.dae</uri>
                    <scale>0.4 0.4 0.4</scale></mesh>
                </geometry>
            </collision>
            <collision name="top_plate_collision_2">
                <pose frame="">0.03248 0.0 0.098 0 0 0</pose>
                <geometry>
                    <box>
                        <size>0.128 0.164 0.036</size>
                    </box>
                </geometry>
            </collision>
            <visual name="X1_1_base_link_visual">
                <pose frame="">0.0 0.0 0.0 0 0 -3.14159</pose>
                <geometry>
                    <mesh>
                        <uri>model://X1/meshes/chassis.dae</uri>
                    <scale>0.4 0.4 0.4</scale></mesh>
                </geometry>
            </visual>
            <visual name="center_left_headlight_visual">
                <pose frame="">0.1943064 0.033760000000000005 0.0497724 0 0 -3.14159</pose>
                <geometry>
                    <mesh>
                        <uri>model://X1/meshes/headlight.dae</uri>
                    <scale>0.4 0.4 0.4</scale></mesh>
                </geometry>
            </visual>
            <visual name="center_right_headlight_visual">
                <pose frame="">0.1943064 -0.033760000000000005 0.0497724 0 0 -3.14159</pose>
                <geometry>
                    <mesh>
                        <uri>model://X1/meshes/headlight.dae</uri>
                    <scale>0.4 0.4 0.4</scale></mesh>
                </geometry>
            </visual>
            <visual name="left_headlight_visual">
                <pose frame="">0.18458360000000001 0.0867212 0.0497724 0 0 -3.14159</pose>
                <geometry>
                    <mesh>
                        <uri>model://X1/meshes/headlight.dae</uri>
                    <scale>0.4 0.4 0.4</scale></mesh>
                </geometry>
            </visual>
            <visual name="right_headlight_visual">
                <pose frame="">0.18458360000000001 -0.0867212 0.0497724 0 0 -3.14159</pose>
                <geometry>
                    <mesh>
                        <uri>model://X1/meshes/headlight.dae</uri>
                    <scale>0.4 0.4 0.4</scale></mesh>
                </geometry>
            </visual>
            <visual name="top_plate_visual">
                <pose frame="">0.03248 0.0 0.098 0 0 0</pose>
                <geometry>
                    <mesh>
                        <uri>model://X1/meshes/top_plate.dae</uri>
                    <scale>0.4 0.4 0.4</scale></mesh>
                </geometry>
            </visual>
            <!--<light name="left_light_source" type="spot">
                <pose frame="">0.514147 0.216803 0.180 3.14159 1.56859 0</pose>
                <attenuation>
                    <range>50</range>
                    <linear>0</linear>
                    <constant>0.1</constant>
                    <quadratic>0.0025</quadratic>
                </attenuation>
                <diffuse>0.8 0.8 0.5 1</diffuse>
                <specular>0.8 0.8 0.5 1</specular>
                <spot>
                    <inner_angle>1</inner_angle>
                    <outer_angle>1.1</outer_angle>
                    <falloff>1</falloff>
                </spot>
                <direction>0 0 -1</direction>
                <cast_shadows>1</cast_shadows>
                <visualize>false</visualize>

            </light>
            <light name="center_left_light" type="spot">
                <pose frame="">0.538 0.0844 0.180 3.14159 1.56859 0</pose>
                <attenuation>
                    <range>50</range>
                    <linear>0</linear>
                    <constant>0.1</constant>
                    <quadratic>0.0025</quadratic>
                </attenuation>
                <diffuse>0.8 0.8 0.5 1</diffuse>
                <specular>0.8 0.8 0.5 1</specular>
                <spot>
                    <inner_angle>1</inner_angle>
                    <outer_angle>1.1</outer_angle>
                    <falloff>1</falloff>
                </spot>
                <direction>0 0 -1</direction>
                <cast_shadows>1</cast_shadows>
                <visualize>false</visualize>
            </light>
            <light name="center_right_light" type="spot">
                <pose frame="">0.538 -0.0844 0.180 3.14159 1.56859 0</pose>
                <attenuation>
                    <range>50</range>
                    <linear>0</linear>
                    <constant>0.1</constant>
                    <quadratic>0.0025</quadratic>
                </attenuation>
                <diffuse>0.8 0.8 0.5 1</diffuse>
                <specular>0.8 0.8 0.5 1</specular>
                <spot>
                    <inner_angle>1</inner_angle>
                    <outer_angle>1.1</outer_angle>
                    <falloff>1</falloff>
                </spot>
                <direction>0 0 -1</direction>
                <cast_shadows>1</cast_shadows>
                <visualize>false</visualize>
            </light>
            <light name="right_light_source" type="spot">
                <pose frame="">0.514147 -0.216803 0.180 3.14159 1.56859 0</pose>
                <attenuation>
                    <range>50</range>
                    <linear>0</linear>
                    <constant>0.1</constant>
                    <quadratic>0.0025</quadratic>
                </attenuation>
                <diffuse>0.8 0.8 0.5 1</diffuse>
                <specular>0.8 0.8 0.5 1</specular>
                <spot>
                    <inner_angle>1</inner_angle>
                    <outer_angle>1.1</outer_angle>
                    <falloff>1</falloff>
                </spot>
                <direction>0 0 -1</direction>
                <cast_shadows>1</cast_shadows>
                <visualize>false</visualize>
            </light> -->


            <sensor name="gpu_lidar" type="gpu_lidar">
                <pose relative_to="X1_1_base_link">0 0 .14 0 0 0</pose>
                <topic>lidar1</topic>
                <update_rate>5</update_rate>
                <ray>
                    <scan>
                        <horizontal>
                        <samples>640</samples>
                        <resolution>1</resolution>
                        <min_angle>-1.396263</min_angle>
                        <max_angle>1.396263</max_angle>
                        </horizontal>
                        <vertical>
                        <samples>1</samples>
                        <resolution>0.01</resolution>
                        <min_angle>0</min_angle>
                        <max_angle>0</max_angle>
                        </vertical>
                    </scan>
                    <range>
                        <min>0.08</min>
                        <max>4</max>
                        <resolution>0.01</resolution>
                    </range>
                </ray>
                <always_on>1</always_on>
                <visualize>true</visualize>
            </sensor>
        </link>


    <!-- Links -->
    <link name="X1_1_front_left_wheel_link">
        <pose frame="">0.1024 0.11416 0.013128 0 0 0</pose> <!-- Position of wheel -->
        <inertial>
            <mass>2.637</mass>
            <inertia>
                <ixx>0.02467</ixx>
                <ixy>0.001</ixy>
                <ixz>0.001</ixz>
                <iyy>0.04411</iyy>
                <iyz>0.001</iyz>
                <izz>0.02467</izz>
            </inertia>
        </inertial>
        <collision name="collision">
            <pose frame="">0.0 0.0 0.0 -1.5707963267948966 0 0</pose>
            <geometry>
                <cylinder>
                    <length>0.045720000000000004</length>
                    <radius>0.06604</radius>
                </cylinder>
            </geometry>
            <surface>
                <friction>
                    <ode>
                        <mu>0.5</mu>
                        <mu2>1</mu2>
                        <slip1>0.00062</slip1>
                        <slip2>0</slip2>
                        <fdir1>0 0 1</fdir1>
                    </ode>
                </friction>
            </surface>
        </collision>
        <visual name="visual">
            <geometry>
                <mesh>
                    <uri>model://X1/meshes/wheel.dae</uri>
                <scale>0.4 0.4 0.4</scale></mesh>
            </geometry>
        </visual>
    </link>

    <link name="X1_1_front_right_wheel_link">
        <pose frame="">0.1024 -0.11416 0.013128 0 0 0</pose> <!-- Position of wheel -->
        <inertial>
            <mass>2.637</mass>
            <inertia>
                <ixx>0.02467</ixx>
                <ixy>0.001</ixy>
                <ixz>0.001</ixz>
                <iyy>0.04411</iyy>
                <iyz>0.001</iyz>
                <izz>0.02467</izz>
            </inertia>
        </inertial>
        <collision name="collision">
            <pose frame="">0.0 0.0 0.0 -1.5707963267948966 0 0</pose>
            <geometry>
                <cylinder>
                    <length>0.045720000000000004</length>
                    <radius>0.06604</radius>
                </cylinder>
            </geometry>
            <surface>
                <friction>
                    <ode>
                        <mu>0.1</mu>
                        <mu2>1</mu2>
                        <slip1>0.00062</slip1>
                        <slip2>0</slip2>
                        <fdir1>0 0 1</fdir1>
                    </ode>
                </friction>
            </surface>
        </collision>
        <visual name="visual">
            <geometry>
                <mesh>
                    <uri>model://X1/meshes/wheel.dae</uri>
                <scale>0.4 0.4 0.4</scale></mesh>
            </geometry>
        </visual>
    </link>

    <link name="X1_1_rear_left_wheel">
        <pose frame="">-0.1024 0.11416 0.013128 0 0 0</pose>
        <inertial>
            <mass>2.637</mass>
            <inertia>
                <ixx>0.02467</ixx>
                <ixy>0.001</ixy>
                <ixz>0.001</ixz>
                <iyy>0.04411</iyy>
                <iyz>0.001</iyz>
                <izz>0.02467</izz>
            </inertia>
        </inertial>
        <collision name="collision">
            <pose frame="">0.0 0.0 0.0 -1.5707963267948966 0 0</pose>
            <geometry>
                <cylinder>
                    <length>0.045720000000000004</length>
                    <radius>0.06604</radius>
                </cylinder>
            </geometry>
            <surface>
                <friction>
                    <ode>
                        <mu>0.5</mu>
                        <mu2>1</mu2>
                        <slip1>0.00062</slip1>
                        <slip2>0</slip2>
                        <fdir1>0 0 1</fdir1>
                    </ode>
                </friction>
            </surface>
        </collision>
        <visual name="visual">
            <geometry>
                <mesh>
                    <uri>model://X1/meshes/wheel.dae</uri>
                <scale>0.4 0.4 0.4</scale></mesh>
            </geometry>
        </visual>
    </link>

    <link name="X1_1_rear_right_wheel">
        <pose frame="">-0.1024 -0.11416 0.013128 0 0 0</pose>
        <inertial>
            <mass>2.637</mass>
            <inertia>
                <ixx>0.02467</ixx>
                <ixy>0.001</ixy>
                <ixz>0.001</ixz>
                <iyy>0.04411</iyy>
                <iyz>0.001</iyz>
                <izz>0.02467</izz>
            </inertia>
        </inertial>
        <collision name="collision">
            <pose frame="">0.0 0.0 0.0 -1.5707963267948966 0 0</pose>
            <geometry>
                <cylinder>
                    <length>0.045720000000000004</length>
                    <radius>0.06604</radius>
                </cylinder>
            </geometry>
            <surface>
                <friction>
                    <ode>
                        <mu>0.5</mu>
                        <mu2>1</mu2>
                        <slip1>0.00062</slip1>
                        <slip2>0</slip2>
                        <fdir1>0 0 1</fdir1>
                    </ode>
                </friction>
            </surface>
        </collision>
        <visual name="visual">
            <geometry>
                <mesh>
                    <uri>model://X1/meshes/wheel.dae</uri>
                <scale>0.4 0.4 0.4</scale></mesh>
            </geometry>
        </visual>
    </link>

    <!-- Steering Links-->
    <link name="X1_1_front_left_steering_link">
        <pose>0.1024 0.11416 0.013128 0 0 0</pose> <!-- Position relative to X1_1_base_link -->

        <inertial>
            <mass>0.01</mass>
            <inertia>
                <ixx>0.001</ixx>
                <iyy>0.001</iyy>
                <izz>0.001</izz>
            </inertia>
        </inertial>

        <collision name="collision">
            <geometry>
                <cylinder>
                    <length>0.0004</length>
                    <radius>0.004</radius>
                </cylinder>
            </geometry>
        </collision>

        <visual name="visual">
            <geometry>
                <cylinder>
                    <length>0.0004</length>
                    <radius>0.004</radius>
                </cylinder>
            </geometry>
        </visual>
    </link>
    <link name="X1_1_front_right_steering_link">
        <pose>0.1024 -0.11416 0.013128 0 0 0</pose> <!-- Position relative to X1_1_base_link -->

        <inertial>
            <mass>0.01</mass>
            <inertia>
                <ixx>0.001</ixx>
                <iyy>0.001</iyy>
                <izz>0.001</izz>
            </inertia>
        </inertial>

        <collision name="collision">
            <geometry>
                <cylinder>
                    <length>0.0004</length>
                    <radius>0.004</radius>
                </cylinder>
            </geometry>
        </collision>

        <visual name="visual">
            <geometry>
                <cylinder>
                    <length>0.0004</length>
                    <radius>0.004</radius>
                </cylinder>
            </geometry>
        </visual>
    </link>



    <!-- Steering Joints -->
    <joint name="X1_1_front_left_steering_joint" type="revolute">
        <parent>X1_1_base_link</parent>
        <child>X1_1_front_left_steering_link</child>
        <axis>
            <xyz>0 0 1</xyz> <!-- Steering happens around the z-axis -->
            <limit>
                <lower>-0.785</lower> <!-- steering angle range: -45째 to 45째 -->
                <upper>0.785</upper>
                <effort>10</effort> <!-- Max effort (torque) limit -->
            </limit>
        </axis>
    </joint>

    <joint name="X1_1_front_right_steering_joint" type="revolute">
        <parent>X1_1_base_link</parent>
        <child>X1_1_front_right_steering_link</child>
        <axis>
            <xyz>0 0 1</xyz> <!-- Steering happens around the z-axis -->
            <limit>
                <lower>-0.785</lower> <!-- steering angle range: -45째 to 45째 (adjust as needed) -->
                <upper>0.785</upper>
                <effort>10</effort> <!-- Max effort (torque) limit -->

            </limit>
        </axis>
    </joint>

    
    <!-- Wheel Joints -->
    <joint name="X1_1_front_left_wheel_joint" type="revolute">
        <parent>X1_1_front_left_steering_link</parent>
        <child>X1_1_front_left_wheel_link</child>
        <axis>
            <xyz>0 1 0</xyz>
            <limit>
                <lower>-1.79769e+308</lower>
                <upper>+1.79769e+308</upper>
            </limit>
        </axis>
    </joint>

    <joint name="X1_1_front_right_wheel_joint" type="revolute">
        <parent>X1_1_front_right_steering_link</parent>
        <child>X1_1_front_right_wheel_link</child>
        <axis>
            <xyz>0 1 0</xyz>
            <limit>
                <lower>-1.79769e+308</lower>
                <upper>+1.79769e+308</upper>
            </limit>
        </axis>
    </joint>

    <joint name="X1_1_rear_left_wheel_joint" type="revolute">
        <parent>X1_1_base_link</parent>
        <child>X1_1_rear_left_wheel</child>
        <axis>
            <xyz>0 1 0</xyz>
            <limit>
                <lower>-1.79769e+308</lower>
                <upper>+1.79769e+308</upper>
                <effort>10</effort>
            </limit>
        </axis>
    </joint>

    <joint name="X1_1_rear_right_wheel_joint" type="revolute">
        <child>X1_1_rear_right_wheel</child>
        <parent>X1_1_base_link</parent>
        <axis>
            <xyz>0 1 0</xyz>
            <limit>
                <lower>-1.79769e+308</lower>
                <upper>+1.79769e+308</upper>
                <effort>10</effort>
            </limit>
        </axis>
    </joint>
   <plugin filename="gz-sim-ackermann-steering-system" name="gz::sim::systems::AckermannSteering">
        <left_joint>X1_1_rear_left_wheel_joint</left_joint>
        <right_joint>X1_1_rear_right_wheel_joint</right_joint>


        <left_steering_joint>X1_1_front_left_steering_joint</left_steering_joint>
        <right_steering_joint>X1_1_front_right_steering_joint</right_steering_joint>

        <kingpin_width>0.2</kingpin_width>
        <wheel_separation>0.22832</wheel_separation>
        <wheel_base>0.2448</wheel_base>
        <wheel_radius>0.06604</wheel_radius>

        <max_velocity>1.0</max_velocity>
        <max_acceleration>7</max_acceleration>
        <steer_p_gain>40</steer_p_gain>
        <steering_limit>1.047</steering_limit>

        <odom_publish_frequency>100</odom_publish_frequency>


        <topic>/model/X1_1/cmd_vel</topic>

    </plugin>
    <plugin filename="gz-sim-pose-publisher-system" name="gz::sim::systems::PosePublisher">
        <use_pose_vector_msg>false</use_pose_vector_msg>
        <publish_nested_model_pose>true</publish_nested_model_pose>
        <publish_model_pose>true</publish_model_pose>
        <static_update_frequency>20</static_update_frequency>
    </plugin>
    <plugin filename="ignition-gazebo-joint-state-publisher-system" name="ignition::gazebo::systems::JointStatePublisher"/>

    
    </model>
</sdf>
