<?xml version="1.0" ?>
<!-- =================================================================================== -->
<!-- |    This document was autogenerated by xacro from src/my_robot_package/urdf/model.urdf.xacro | -->
<!-- |    EDITING THIS FILE BY HAND IS NOT RECOMMENDED                                 | -->
<!-- =================================================================================== -->
<robot name="converted_robot">
  <link name="X1_2_base_link">
    <visual>
      <origin rpy="0 0 -3.14" xyz="0 0 0"/>
      <geometry>
        <mesh filename="package://my_robot_package/meshes/chassis.dae" scale="0.4 0.4 0.4"/>
        <scale value=".4 .4 .4"/>
      </geometry>
    </visual>
    <collision name="base_link_collision">
      <origin rpy="0 0 0" xyz="0 0 0.12"/>
      <geometry>
        <!-- 0.39496000000000003 0.22836 0.020000000000000004-->
        <box size=".3949 0.22836 0.02"/>
      </geometry>
    </collision>
  </link>
  <link name="X1_2_front_left_wheel_link">
    <visual>
      <geometry>
        <mesh filename="package://my_robot_package/meshes/wheel.dae" scale="0.4 0.4 0.4"/>
      </geometry>
    </visual>
    <collision name="front_left_wheel_collision">
      <origin rpy="-1.57 0 0" xyz="0 0 0"/>
      <geometry>
        <cylinder length="0.0457" radius="0.06604"/>
      </geometry>
    </collision>
  </link>
  <link name="X1_2_front_right_wheel_link">
    <visual>
      <geometry>
        <mesh filename="package://my_robot_package/meshes/wheel.dae" scale="0.4 0.4 0.4"/>
        <!--<mesh filename="/home/gio2/Robotics/freshStart/ros2_ws/src/my_robot_package/meshes/wheel.dae"/>-->
      </geometry>
    </visual>
    <collision name="front_right_wheel_collision">
      <origin rpy="-1.57 0 0" xyz="0 0 0"/>
      <geometry>
        <cylinder length="0.0457" radius="0.06604"/>
      </geometry>
    </collision>
  </link>
  <link name="X1_2_rear_left_wheel_link">
    <visual>
      <geometry>
        <mesh filename="package://my_robot_package/meshes/wheel.dae" scale="0.4 0.4 0.4"/>
      </geometry>
    </visual>
    <collision name="rear_left_wheel_collision">
      <origin rpy="-1.57 0 0" xyz="0 0 0"/>
      <geometry>
        <cylinder length="0.0457" radius="0.06604"/>
      </geometry>
    </collision>
  </link>
  <link name="X1_2_rear_right_wheel_link">
    <visual>
      <geometry>
        <mesh filename="package://my_robot_package/meshes/wheel.dae" scale="0.4 0.4 0.4"/>
      </geometry>
    </visual>
    <collision name="rear_right_wheel_collision">
      <origin rpy="-1.57 0 0" xyz="0 0 0"/>
      <geometry>
        <cylinder length="0.0457" radius="0.06604"/>
      </geometry>
    </collision>
  </link>
  <!-- <link name="front_left_steering_link">
    <visual>
      <geometry>
        <cylinder length="0.0001" radius="0.01"/>
      </geometry>
    </visual>
    <collision name="front_left_steering_link_collision">
      <geometry>
        <cylinder length="0.0001" radius="0.01"/>
      </geometry>
    </collision>
  </link>

    <link name="front_right_steering_link">
    <visual>
      <geometry>
        <cylinder length="0.0001" radius="0.01"/>
      </geometry>
    </visual>
    <collision name="front_right_steering_link_collision">
      <geometry>
        <cylinder length="0.0001" radius="0.01"/>
      </geometry>
    </collision>
  </link>

  <joint name="front_left_steering_joint" type="revolute">
    <parent link="base_link"/>
    <child link="front_left_steering_link"/>
    <axis xyz=" 0 0 1"/>
  </joint>

  <joint name="front_right_steering_joint" type="revolute">
    <parent link="base_link"/>
    <child link="front_right_steering_link"/>
    <axis xyz=" 0 0 1"/>
  </joint> -->
  <joint name="X1_2_front_left_wheel_joint" type="continuous">
    <parent link="X1_2_base_link"/>
    <child link="X1_2_front_left_wheel_link"/>
    <origin rpy="0 0 0" xyz="0.10 0.11 0.01"/>
    <axis xyz="0 1 0"/>
  </joint>
  <joint name="X1_2_front_right_wheel_joint" type="continuous">
    <parent link="X1_2_base_link"/>
    <child link="X1_2_front_right_wheel_link"/>
    <origin rpy="0 0 0" xyz="0.10 -0.11 0.01"/>
    <axis xyz="0 1 0"/>
  </joint>
  <joint name="X1_2_rear_left_wheel_joint" type="continuous">
    <parent link="X1_2_base_link"/>
    <child link="X1_2_rear_left_wheel_link"/>
    <origin rpy="0 0 0" xyz="-0.10 0.11 0.01"/>
    <axis xyz="0 1 0"/>
  </joint>
  <joint name="X1_2_rear_right_wheel_joint" type="continuous">
    <parent link="X1_2_base_link"/>
    <child link="X1_2_rear_right_wheel_link"/>
    <origin rpy="0 0 0" xyz="-0.10 -0.11 0.01"/>
    <axis xyz="0 1 0"/>
  </joint>
</robot>
