<?xml version="1.0" ?>
<!-- =================================================================================== -->
<!-- |    This document was autogenerated by xacro from /home/gio2/Robotics/freshStart/ros2_ws/src/my_robot_package/urdf/model.urdf.xacro | -->
<!-- |    EDITING THIS FILE BY HAND IS NOT RECOMMENDED                                 | -->
<!-- =================================================================================== -->
<robot name="converted_robot">
  <link name="X1_2_base_link">
    <visual>
      <origin rpy="0 0 -3.14" xyz="0 0 0"/>
      <geometry>
        <mesh filename="package://my_robot_package/meshes/chassis.dae"/>
      </geometry>
    </visual>
    <collision name="base_link_collision">
      <origin rpy="0 0 0" xyz="0 0 0.12"/>
      <geometry>
        <box size=".98 .57 .05"/>
      </geometry>
    </collision>
  </link>
  <link name="X1_2_front_left_wheel_link">
    <visual>
      <geometry>
        <mesh filename="package://my_robot_package/meshes/wheel.dae"/>
      </geometry>
    </visual>
    <collision name="front_left_wheel_collision">
      <origin rpy="-1.57 0 0" xyz="0 0 0"/>
      <geometry>
        <cylinder length="0.1143" radius="0.1651"/>
      </geometry>
    </collision>
  </link>
  <link name="X1_2_front_right_wheel_link">
    <visual>
      <geometry>
        <mesh filename="package://my_robot_package/meshes/wheel.dae"/>
        <!--<mesh filename="/home/gio2/Robotics/freshStart/ros2_ws/src/my_robot_package/meshes/wheel.dae"/>-->
      </geometry>
    </visual>
    <collision name="front_right_wheel_collision">
      <origin rpy="-1.57 0 0" xyz="0 0 0"/>
      <geometry>
        <cylinder length="0.1143" radius="0.1651"/>
      </geometry>
    </collision>
  </link>
  <link name="X1_2_rear_left_wheel_link">
    <visual>
      <geometry>
        <mesh filename="package://my_robot_package/meshes/wheel.dae"/>
      </geometry>
    </visual>
    <collision name="rear_left_wheel_collision">
      <origin rpy="-1.57 0 0" xyz="0 0 0"/>
      <geometry>
        <cylinder length="0.1143" radius="0.1651"/>
      </geometry>
    </collision>
  </link>
  <link name="X1_2_rear_right_wheel_link">
    <visual>
      <geometry>
        <mesh filename="package://my_robot_package/meshes/wheel.dae"/>
      </geometry>
    </visual>
    <collision name="rear_right_wheel_collision">
      <origin rpy="-1.57 0 0" xyz="0 0 0"/>
      <geometry>
        <cylinder length="0.1143" radius="0.1651"/>
      </geometry>
    </collision>
  </link>
  <!-- <link name="front_left_steering_link">
    <visual>
      <geometry>
        <cylinder length="0.0001" radius="0.01"/>
      </geometry>
    </visual>
    <collision name="front_left_steering_link_collision">
      <geometry>
        <cylinder length="0.0001" radius="0.01"/>
      </geometry>
    </collision>
  </link>

    <link name="front_right_steering_link">
    <visual>
      <geometry>
        <cylinder length="0.0001" radius="0.01"/>
      </geometry>
    </visual>
    <collision name="front_right_steering_link_collision">
      <geometry>
        <cylinder length="0.0001" radius="0.01"/>
      </geometry>
    </collision>
  </link>

  <joint name="front_left_steering_joint" type="revolute">
    <parent link="base_link"/>
    <child link="front_left_steering_link"/>
    <axis xyz=" 0 0 1"/>
  </joint>

  <joint name="front_right_steering_joint" type="revolute">
    <parent link="base_link"/>
    <child link="front_right_steering_link"/>
    <axis xyz=" 0 0 1"/>
  </joint> -->
  <joint name="X1_2_front_left_wheel_joint" type="continuous">
    <parent link="X1_2_base_link"/>
    <child link="X1_2_front_left_wheel_link"/>
    <origin rpy="0 0 0" xyz="0.256 0.2854 0.03282"/>
    <axis xyz="0 1 0"/>
  </joint>
  <joint name="X1_2_front_right_wheel_joint" type="continuous">
    <parent link="X1_2_base_link"/>
    <child link="X1_2_front_right_wheel_link"/>
    <origin rpy="0 0 0" xyz="0.256 -0.2854 0.03282"/>
    <axis xyz="0 1 0"/>
  </joint>
  <joint name="X1_2_rear_left_wheel_joint" type="continuous">
    <parent link="X1_2_base_link"/>
    <child link="X1_2_rear_left_wheel_link"/>
    <origin rpy="0 0 0" xyz="-0.256 0.2854 0.03282"/>
    <axis xyz="0 1 0"/>
  </joint>
  <joint name="X1_2_rear_right_wheel_joint" type="continuous">
    <parent link="X1_2_base_link"/>
    <child link="X1_2_rear_right_wheel_link"/>
    <origin rpy="0 0 0" xyz="-0.256 -0.2854 0.03282"/>
    <axis xyz="0 1 0"/>
  </joint>
</robot>
